<?xml version="1.0" ?>
<!-- =================================================================================== -->
<!-- |    This document was autogenerated by xacro from src/BD1/bd1_description/urdf/bd1.xacro | -->
<!-- |    EDITING THIS FILE BY HAND IS NOT RECOMMENDED                                 | -->
<!-- =================================================================================== -->
<robot name="BD1">
  <!--<xacro:property name="servo_friction" value="1000"/>-->
  <!--  <gazebo reference="body_link">    
    <sensor type="contact" name="body_contact_sensor">
        <update_rate>100.0</update_rate>
        <always_on>1</always_on>
        <contact>
            <collision>body_link_collision</collision>
            <topic>/body_collision</topic>
        </contact>
        <plugin name="gazebo_ros_bumper_controller" filename="libgazebo_ros_bumper.so">
            <alwaysOn>true</alwaysOn>
            <updateRate>1000.0</updateRate>
            <bumperTopicName>/robot_bumper</bumperTopicName>
            <frameName>world</frameName>
        </plugin>
    </sensor>
  </gazebo>-->
  <gazebo reference="body_link">
    <contact>
      <collision>body_link_collision__collision</collision>
    </contact>
    <plugin filename="libcontact.so" name="body_link_gazebo_ros_bumper_controller">
      <alwaysOn>true</alwaysOn>
      <updateRate>100</updateRate>
      <bumperTopicName>body_link_bumper</bumperTopicName>
      <frameName>world</frameName>
    </plugin>
  </gazebo>
  <gazebo>
    <plugin filename="libgazebo_ros_control.so" name="gazebo_ros_control">
      <robotSimType>gazebo_ros_control/DefaultRobotHWSim</robotSimType>
      <legacyModeNS>true</legacyModeNS>
    </plugin>
  </gazebo>
  <selfCollide>true</selfCollide>
  <!--
        BASE
    -->
  <link name="base_link">
    </link>
  <!--
        BODY
    -->
  <link name="body_link">
    <visual>
      <geometry>
        <mesh filename="file:///mesh/body_m.dae"/>
        <!--<box size="${body_aprox_x} ${body_aprox_y} ${body_aprox_z}"/>-->
      </geometry>
      <material name="white">
        <color rgba="1 1 1 1"/>
      </material>
    </visual>
    <collision name="body_link_collision">
      <origin rpy=" 0 0 0" xyz="-0.015 0.0 0.005"/>
      <geometry>
        <box size="0.18 0.12 0.1"/>
      </geometry>
    </collision>
    <inertial>
      <origin rpy=" 0 0 0" xyz="-0.015 0.0 0.005"/>
      <mass value="0.5"/>
      <inertia ixx="0.0009760000000000001" ixy="0" ixz="0" iyy="0.001696" iyz="0" izz="0.0018719999999999997"/>
    </inertial>
  </link>
  <joint name="body_j" type="fixed">
    <parent link="base_link"/>
    <child link="body_link"/>
    <origin rpy="0 0 0" xyz="0 0 0"/>
  </joint>
  <!--
        NECK
    -->
  <link name="neck_link">
    <visual>
      <geometry>
        <mesh filename="file:///mesh/neck_m.dae"/>
      </geometry>
    </visual>
    <inertial>
      <mass value="0.1"/>
      <inertia ixx="0.0008720000000000003" ixy="0" ixz="0" iyy="0.0008320000000000003" iyz="0" izz="0.00010400000000000002"/>
      <origin rpy=" 0 0 0" xyz="0 0 0.035"/>
    </inertial>
  </link>
  <joint name="neck_j" type="revolute">
    <parent link="body_link"/>
    <child link="neck_link"/>
    <origin rpy="0 0 0" xyz="0.03 0.0 0.04"/>
    <limit effort="30" lower="-1.5707963267948966" upper="1.5707963267948966" velocity="2"/>
    <axis xyz="0 -1 0"/>
    <dynamics damping="0.3"/>
  </joint>
  <transmission name="neck_j_transm">
    <type>transmission_interface/SimpleTransmission</type>
    <joint name="neck_j">
      <hardwareInterface>hardware_interface/VelocityJointInterface</hardwareInterface>
    </joint>
    <actuator name="neck_j_motor">
      <hardwareInterface>hardware_interface/VelocityActuatorInterface</hardwareInterface>
    </actuator>
  </transmission>
  <!--
        HEAD
    -->
  <link name="head_link">
    <visual>
      <geometry>
        <mesh filename="file:///mesh/head_m.dae"/>
        <!--<box size="${head_aprox_x} ${head_aprox_y} ${head_aprox_z}"/>-->
      </geometry>
      <material name="white">
        <color rgba="1 1 1 1"/>
      </material>
    </visual>
    <collision>
      <origin rpy=" 0 0 0" xyz="0.04 0.0 0.07"/>
      <geometry>
        <box size="0.29 0.24 0.08"/>
      </geometry>
    </collision>
    <inertial>
      <origin rpy=" 0 0 0" xyz="0.04 0.0 0.07"/>
      <mass value="0.5"/>
      <inertia ixx="0.00256" ixy="0" ixz="0" iyy="0.00362" iyz="0" izz="0.005667999999999999"/>
    </inertial>
  </link>
  <joint name="head_j" type="revolute">
    <parent link="neck_link"/>
    <child link="head_link"/>
    <origin rpy="0 0 0" xyz="0 0 0.07"/>
    <limit effort="30" lower="0" upper="1.5707963267948966" velocity="2"/>
    <axis xyz="0 1 0"/>
    <dynamics damping="0.3"/>
  </joint>
  <transmission name="head_j_transm">
    <type>transmission_interface/SimpleTransmission</type>
    <joint name="head_j">
      <hardwareInterface>hardware_interface/VelocityJointInterface</hardwareInterface>
    </joint>
    <actuator name="head_j_motor">
      <hardwareInterface>hardware_interface/VelocityActuatorInterface</hardwareInterface>
    </actuator>
  </transmission>
  <!--
        hip
        -->
  <link name="hip_r_link">
    <visual>
      <geometry>
        <mesh filename="file:///mesh/hip_r_m.dae"/>
        <!--<box size="${hip_aprox_x} ${hip_aprox_y} ${hip_aprox_z}"/>-->
      </geometry>
      <material name="white">
        <color rgba="1 1 1 1"/>
      </material>
    </visual>
    <collision>
      <origin rpy=" 0 0 0" xyz="0.065 -0.03 0.0"/>
      <geometry>
        <box size="0.22 0.02 0.06"/>
      </geometry>
    </collision>
    <inertial>
      <origin rpy=" 0 0 0" xyz="0.065 -0.03 0.0"/>
      <mass value="0.25"/>
      <inertia ixx="8e-05" ixy="0" ixz="0" iyy="0.00104" iyz="0" izz="0.000976"/>
    </inertial>
  </link>
  <joint name="hip_r_j" type="revolute">
    <parent link="body_link"/>
    <child link="hip_r_link"/>
    <origin rpy="0 1.5707963267948966 0" xyz="0 -0.06 0"/>
    <limit effort="30" lower="-1.5707963267948966" upper="0" velocity="2"/>
    <axis xyz="0 -1 0"/>
    <!--<dynamics damping="${servo_friction}"/>-->
  </joint>
  <transmission name="hip_r_j_transm">
    <type>transmission_interface/SimpleTransmission</type>
    <joint name="hip_r_j">
      <hardwareInterface>hardware_interface/VelocityJointInterface</hardwareInterface>
    </joint>
    <actuator name="hip_r_j_motor">
      <hardwareInterface>hardware_interface/VelocityActuatorInterface</hardwareInterface>
    </actuator>
  </transmission>
  <!--
        knee
        -->
  <link name="knee_r_link">
    <visual>
      <geometry>
        <mesh filename="file:///mesh/knee_r_m.dae"/>
        <!--<box size="${hip_aprox_x} ${hip_aprox_y} ${hip_aprox_z}"/>-->
      </geometry>
      <material name="white">
        <color rgba="1 1 1 1"/>
      </material>
    </visual>
    <collision>
      <origin rpy=" 0 0 0" xyz="0.07 0.01 0.0"/>
      <geometry>
        <box size="0.22 0.02 0.06"/>
      </geometry>
    </collision>
    <inertial>
      <origin rpy=" 0 0 0" xyz="0.07 0.01 0.0"/>
      <mass value="0.25"/>
      <inertia ixx="8e-05" ixy="0" ixz="0" iyy="0.00104" iyz="0" izz="0.000976"/>
    </inertial>
  </link>
  <joint name="knee_r_j" type="revolute">
    <parent link="hip_r_link"/>
    <child link="knee_r_link"/>
    <origin rpy="0 0 0" xyz="0.15 -0.009 0"/>
    <limit effort="30" lower="0" upper="3.141592653589793" velocity="2"/>
    <axis xyz="0 -1 0"/>
    <!--<dynamics damping="${servo_friction}"/>-->
  </joint>
  <transmission name="knee_r_j_transm">
    <type>transmission_interface/SimpleTransmission</type>
    <joint name="knee_r_j">
      <hardwareInterface>hardware_interface/VelocityJointInterface</hardwareInterface>
    </joint>
    <actuator name="knee_r_j_motor">
      <hardwareInterface>hardware_interface/VelocityActuatorInterface</hardwareInterface>
    </actuator>
  </transmission>
  <!--
        foot
        -->
  <link name="foot_r_link">
    <visual>
      <geometry>
        <mesh filename="file:///mesh/foot_m.dae"/>
        <!--<box size="${foot_aprox_x} ${foot_aprox_y} ${foot_aprox_z}"/>-->
      </geometry>
      <material name="white">
        <color rgba="1 1 1 1"/>
      </material>
    </visual>
    <collision>
      <origin rpy=" 0 0 0" xyz="0.1 0.0 -0.065"/>
      <geometry>
        <box size="0.09 0.06 0.025"/>
      </geometry>
    </collision>
    <inertial>
      <origin rpy=" 0 0 0" xyz="0.1 0.0 -0.065"/>
      <mass value="0.25"/>
      <inertia ixx="8.45e-05" ixy="0" ixz="0" iyy="0.0001745" iyz="0" izz="0.00023399999999999997"/>
    </inertial>
  </link>
  <joint name="foot_r_j" type="revolute">
    <parent link="knee_r_link"/>
    <child link="foot_r_link"/>
    <origin rpy="0 -1.5707963267948966 0" xyz="0.15 0.0045 0"/>
    <limit effort="30" lower="-1.5707963267948966" upper="1.5707963267948966" velocity="2"/>
    <axis xyz="0 1 0"/>
    <!--<dynamics damping="${servo_friction}"/>-->
  </joint>
  <gazebo reference="foot_r_link">
    <!--<material>Gazebo/Black</material>-->
    <mu1>2</mu1>
    <mu2>5</mu2>
    <!--<dampingFactor>0.05</dampingFactor>-->
    <kp>100000</kp>
    <kd>1</kd>
  </gazebo>
  <transmission name="foot_r_j_transm">
    <type>transmission_interface/SimpleTransmission</type>
    <joint name="foot_r_j">
      <hardwareInterface>hardware_interface/VelocityJointInterface</hardwareInterface>
    </joint>
    <actuator name="foot_r_j_motor">
      <hardwareInterface>hardware_interface/VelocityActuatorInterface</hardwareInterface>
    </actuator>
  </transmission>
  <!-- heel -->
  <link name="heel_r_link">
    <!--<visual>            
                <geometry>                    
                    <box size="${heel_aprox_x} ${heel_aprox_y} ${heel_aprox_z}"/>
                </geometry>
                <material name="white">
                    <color rgba="1 1 1 1"/>
                </material>
            </visual>-->
    <collision>
      <origin rpy=" 0 0 0" xyz="-0.08 0.0 -0.065"/>
      <geometry>
        <box size="0.06 0.06 0.025"/>
      </geometry>
    </collision>
    <inertial>
      <origin rpy=" 0 0 0" xyz="-0.08 0.0 -0.065"/>
      <mass value="0.15"/>
      <inertia ixx="5.07e-05" ixy="0" ixz="0" iyy="5.07e-05" iyz="0" izz="8.64e-05"/>
    </inertial>
  </link>
  <joint name="heel_r_j" type="fixed">
    <parent link="foot_r_link"/>
    <child link="heel_r_link"/>
    <origin rpy="0 0 0" xyz="0 0 0"/>
    <!--<limit effort="${servo_effort}" velocity="${servo_velocity}" lower="${-pi}" hipper="0"/>-->
    <!--<axis xyz="0 1 0"/>-->
    <!--<dynamics damping="${servo_friction}"/>-->
  </joint>
  <gazebo reference="heel_r_link">
    <mu1>2</mu1>
    <mu2>5</mu2>
    <kp>100000</kp>
    <kd>1</kd>
  </gazebo>
  <!--
        hip
        -->
  <link name="hip_l_link">
    <visual>
      <geometry>
        <mesh filename="file:///mesh/hip_l_m.dae"/>
        <!--<box size="${hip_aprox_x} ${hip_aprox_y} ${hip_aprox_z}"/>-->
      </geometry>
      <material name="white">
        <color rgba="1 1 1 1"/>
      </material>
    </visual>
    <collision>
      <origin rpy=" 0 0 0" xyz="0.065 0.03 0.0"/>
      <geometry>
        <box size="0.22 0.02 0.06"/>
      </geometry>
    </collision>
    <inertial>
      <origin rpy=" 0 0 0" xyz="0.065 0.03 0.0"/>
      <mass value="0.25"/>
      <inertia ixx="8e-05" ixy="0" ixz="0" iyy="0.00104" iyz="0" izz="0.000976"/>
    </inertial>
  </link>
  <joint name="hip_l_j" type="revolute">
    <parent link="body_link"/>
    <child link="hip_l_link"/>
    <origin rpy="0 1.5707963267948966 0" xyz="0 0.06 0"/>
    <limit effort="30" lower="-1.5707963267948966" upper="0" velocity="2"/>
    <axis xyz="0 -1 0"/>
    <!--<dynamics damping="${servo_friction}"/>-->
  </joint>
  <transmission name="hip_l_j_transm">
    <type>transmission_interface/SimpleTransmission</type>
    <joint name="hip_l_j">
      <hardwareInterface>hardware_interface/VelocityJointInterface</hardwareInterface>
    </joint>
    <actuator name="hip_l_j_motor">
      <hardwareInterface>hardware_interface/VelocityActuatorInterface</hardwareInterface>
    </actuator>
  </transmission>
  <!--
        knee
        -->
  <link name="knee_l_link">
    <visual>
      <geometry>
        <mesh filename="file:///mesh/knee_l_m.dae"/>
        <!--<box size="${hip_aprox_x} ${hip_aprox_y} ${hip_aprox_z}"/>-->
      </geometry>
      <material name="white">
        <color rgba="1 1 1 1"/>
      </material>
    </visual>
    <collision>
      <origin rpy=" 0 0 0" xyz="0.07 -0.01 0.0"/>
      <geometry>
        <box size="0.22 0.02 0.06"/>
      </geometry>
    </collision>
    <inertial>
      <origin rpy=" 0 0 0" xyz="0.07 -0.01 0.0"/>
      <mass value="0.25"/>
      <inertia ixx="8e-05" ixy="0" ixz="0" iyy="0.00104" iyz="0" izz="0.000976"/>
    </inertial>
  </link>
  <joint name="knee_l_j" type="revolute">
    <parent link="hip_l_link"/>
    <child link="knee_l_link"/>
    <origin rpy="0 0 0" xyz="0.15 0.009 0"/>
    <limit effort="30" lower="0" upper="3.141592653589793" velocity="2"/>
    <axis xyz="0 -1 0"/>
    <!--<dynamics damping="${servo_friction}"/>-->
  </joint>
  <transmission name="knee_l_j_transm">
    <type>transmission_interface/SimpleTransmission</type>
    <joint name="knee_l_j">
      <hardwareInterface>hardware_interface/VelocityJointInterface</hardwareInterface>
    </joint>
    <actuator name="knee_l_j_motor">
      <hardwareInterface>hardware_interface/VelocityActuatorInterface</hardwareInterface>
    </actuator>
  </transmission>
  <!--
        foot
        -->
  <link name="foot_l_link">
    <visual>
      <geometry>
        <mesh filename="file:///mesh/foot_m.dae"/>
        <!--<box size="${foot_aprox_x} ${foot_aprox_y} ${foot_aprox_z}"/>-->
      </geometry>
      <material name="white">
        <color rgba="1 1 1 1"/>
      </material>
    </visual>
    <collision>
      <origin rpy=" 0 0 0" xyz="0.1 -0.0 -0.065"/>
      <geometry>
        <box size="0.09 0.06 0.025"/>
      </geometry>
    </collision>
    <inertial>
      <origin rpy=" 0 0 0" xyz="0.1 -0.0 -0.065"/>
      <mass value="0.25"/>
      <inertia ixx="8.45e-05" ixy="0" ixz="0" iyy="0.0001745" iyz="0" izz="0.00023399999999999997"/>
    </inertial>
  </link>
  <joint name="foot_l_j" type="revolute">
    <parent link="knee_l_link"/>
    <child link="foot_l_link"/>
    <origin rpy="0 -1.5707963267948966 0" xyz="0.15 -0.0045 0"/>
    <limit effort="30" lower="-1.5707963267948966" upper="1.5707963267948966" velocity="2"/>
    <axis xyz="0 1 0"/>
    <!--<dynamics damping="${servo_friction}"/>-->
  </joint>
  <gazebo reference="foot_l_link">
    <!--<material>Gazebo/Black</material>-->
    <mu1>2</mu1>
    <mu2>5</mu2>
    <!--<dampingFactor>0.05</dampingFactor>-->
    <kp>100000</kp>
    <kd>1</kd>
  </gazebo>
  <transmission name="foot_l_j_transm">
    <type>transmission_interface/SimpleTransmission</type>
    <joint name="foot_l_j">
      <hardwareInterface>hardware_interface/VelocityJointInterface</hardwareInterface>
    </joint>
    <actuator name="foot_l_j_motor">
      <hardwareInterface>hardware_interface/VelocityActuatorInterface</hardwareInterface>
    </actuator>
  </transmission>
  <!-- heel -->
  <link name="heel_l_link">
    <!--<visual>            
                <geometry>                    
                    <box size="${heel_aprox_x} ${heel_aprox_y} ${heel_aprox_z}"/>
                </geometry>
                <material name="white">
                    <color rgba="1 1 1 1"/>
                </material>
            </visual>-->
    <collision>
      <origin rpy=" 0 0 0" xyz="-0.08 -0.0 -0.065"/>
      <geometry>
        <box size="0.06 0.06 0.025"/>
      </geometry>
    </collision>
    <inertial>
      <origin rpy=" 0 0 0" xyz="-0.08 -0.0 -0.065"/>
      <mass value="0.15"/>
      <inertia ixx="5.07e-05" ixy="0" ixz="0" iyy="5.07e-05" iyz="0" izz="8.64e-05"/>
    </inertial>
  </link>
  <joint name="heel_l_j" type="fixed">
    <parent link="foot_l_link"/>
    <child link="heel_l_link"/>
    <origin rpy="0 0 0" xyz="0 0 0"/>
    <!--<limit effort="${servo_effort}" velocity="${servo_velocity}" lower="${-pi}" hipper="0"/>-->
    <!--<axis xyz="0 1 0"/>-->
    <!--<dynamics damping="${servo_friction}"/>-->
  </joint>
  <gazebo reference="heel_l_link">
    <mu1>2</mu1>
    <mu2>5</mu2>
    <kp>100000</kp>
    <kd>1</kd>
  </gazebo>
</robot>

